Workbook

Sheet Ringkasan
A1: Perbandingan uji noise E1 (load cell diam 60 s)
A2: Hand grip dynamometer. Sumber: log Serial Monitor sketsa uji_bench_hgd. Sel biru = angka dari log; sel kuning = diisi untuk rakitan akhir; sel hitam = rumus.
A4: Skala awal (counts/kg) | B4: 53687
A6: Ukuran | B6: E1 15 Okt | C6: E1 16 Okt (resmi) | D6: E1 rakitan akhir
A7: Tanggal | B7: 15 Okt. 2026 | C7: 16 Okt. 2026
A8: Kondisi | B8: Bench, tanpa pemanasan | C8: Bench, pemanasan ≈ 11 menit | D8: Housing dirakit, pemanasan ≥ 10 menit
A9: Sketsa: jumlah sampel | B9: 706 | C9: 705
A10: Sketsa: rata-rata raw (counts) | B10: -39908.2 | C10: -39097
A11: Sketsa: σ (counts) | B11: 38.2 | C11: 35
A12: Sketsa: peak-to-peak (counts) | B12: 206 | C12: 206
A13: Sketsa: saran THRESHOLD_ONSET_KG (kg) | B13: 1 | C13: 1
A14: Dari baris yang dicetak (rumus)
A15: Jumlah baris | B15: =COUNT('E1 15 Okt'!D5:D244) -> 240 | C15: =COUNT('E1 16 Okt'!D5:D244) -> 240 | D15: =COUNT('E1 rakitan akhir'!D5:D304) -> 0
A16: Rata-rata raw (counts) | B16: =IF(COUNT('E1 15 Okt'!D5:D244)=0,"",AVERAGE('E1 15 Okt'!D5:D244)) -> -39910.971 | C16: =IF(COUNT('E1 16 Okt'!D5:D244)=0,"",AVERAGE('E1 16 Okt'!D5:D244)) -> -39097.446 | D16: =IF(COUNT('E1 rakitan akhir'!D5:D304)=0,"",AVERAGE('E1 rakitan akhir'!D5:D304))
A17: Simpangan baku raw (counts) | B17: =IF(COUNT('E1 15 Okt'!D5:D244)<2,"",STDEV('E1 15 Okt'!D5:D244)) -> 38.258688 | C17: =IF(COUNT('E1 16 Okt'!D5:D244)<2,"",STDEV('E1 16 Okt'!D5:D244)) -> 34.686841 | D17: =IF(COUNT('E1 rakitan akhir'!D5:D304)<2,"",STDEV('E1 rakitan akhir'!D5:D304))
A18: Minimum raw (counts) | B18: =IF(COUNT('E1 15 Okt'!D5:D244)=0,"",MIN('E1 15 Okt'!D5:D244)) -> -39995 | C18: =IF(COUNT('E1 16 Okt'!D5:D244)=0,"",MIN('E1 16 Okt'!D5:D244)) -> -39177 | D18: =IF(COUNT('E1 rakitan akhir'!D5:D304)=0,"",MIN('E1 rakitan akhir'!D5:D304))
A19: Maksimum raw (counts) | B19: =IF(COUNT('E1 15 Okt'!D5:D244)=0,"",MAX('E1 15 Okt'!D5:D244)) -> -39811 | C19: =IF(COUNT('E1 16 Okt'!D5:D244)=0,"",MAX('E1 16 Okt'!D5:D244)) -> -39009 | D19: =IF(COUNT('E1 rakitan akhir'!D5:D304)=0,"",MAX('E1 rakitan akhir'!D5:D304))
A20: Peak-to-peak (counts) | B20: =IF(COUNT('E1 15 Okt'!D5:D244)=0,"",MAX('E1 15 Okt'!D5:D244)-MIN('E1 15 Okt'!D5:D244)) -> 184 | C20: =IF(COUNT('E1 16 Okt'!D5:D244)=0,"",MAX('E1 16 Okt'!D5:D244)-MIN('E1 16 Okt'!D5:D244)) -> 168 | D20: =IF(COUNT('E1 rakitan akhir'!D5:D304)=0,"",MAX('E1 rakitan akhir'!D5:D304)-MIN('E1 rakitan akhir'!D5:D304))
A21: Simpangan baku (kg) | B21: =IF(COUNT('E1 15 Okt'!D5:D244)<2,"",STDEV('E1 15 Okt'!D5:D244)/$B$4) -> 0.0007126248 | C21: =IF(COUNT('E1 16 Okt'!D5:D244)<2,"",STDEV('E1 16 Okt'!D5:D244)/$B$4) -> 0.00064609387 | D21: =IF(COUNT('E1 rakitan akhir'!D5:D304)<2,"",STDEV('E1 rakitan akhir'!D5:D304)/$B$4)
A22: Peak-to-peak (kg) | B22: =IF(COUNT('E1 15 Okt'!D5:D244)=0,"",(MAX('E1 15 Okt'!D5:D244)-MIN('E1 15 Okt'!D5:D244))/$B$4) -> 0.0034272729 | C22: =IF(COUNT('E1 16 Okt'!D5:D244)=0,"",(MAX('E1 16 Okt'!D5:D244)-MIN('E1 16 Okt'!D5:D244))/$B$4) -> 0.0031292492 | D22: =IF(COUNT('E1 rakitan akhir'!D5:D304)=0,"",(MAX('E1 rakitan akhir'!D5:D304)-MIN('E1 rakitan akhir'!D5:D304))/$B$4)
A23: 10σ (kg) | B23: =IF(COUNT('E1 15 Okt'!D5:D244)<2,"",10*STDEV('E1 15 Okt'!D5:D244)/$B$4) -> 0.007126248 | C23: =IF(COUNT('E1 16 Okt'!D5:D244)<2,"",10*STDEV('E1 16 Okt'!D5:D244)/$B$4) -> 0.0064609387 | D23: =IF(COUNT('E1 rakitan akhir'!D5:D304)<2,"",10*STDEV('E1 rakitan akhir'!D5:D304)/$B$4)
A24: Ambang onset = maks(1,0; 10σ) (kg) | B24: =IF(COUNT('E1 15 Okt'!D5:D244)<2,"",MAX(1,10*STDEV('E1 15 Okt'!D5:D244)/$B$4)) -> 1 | C24: =IF(COUNT('E1 16 Okt'!D5:D244)<2,"",MAX(1,10*STDEV('E1 16 Okt'!D5:D244)/$B$4)) -> 1 | D24: =IF(COUNT('E1 rakitan akhir'!D5:D304)<2,"",MAX(1,10*STDEV('E1 rakitan akhir'!D5:D304)/$B$4))
A26: σ dari sketsa memakai semua sampel (≈ 11,8/s); baris log hanya 4/s, jadi angka rumus sedikit berbeda. Bandingkan run dengan cara yang sama (sketsa vs sketsa, rumus vs rumus).

Sheet E1 16 Okt
A1: E1 resmi 16 Okt. 2026 (setelah pemanasan ≈ 11 menit)
A2: Baris yang dicetak sketsa uji_bench_hgd selama E1 (4 baris/s; sketsa menghitung σ dari semua sampel ≈ 11,8/s, jadi statistik dari baris ini sedikit berbeda dari ringkasan sketsa). Nilai biru = disalin dari log Serial Monitor. t perkiraan = (No − 1) × 0,25 s.
A4: No | B4: Baris log | C4: t perkiraan (s) | D4: raw (counts) | E4: kg (skala awal) | F4: win_avg (kg) | G4: spread (kg) | H4: Tanda | I4: raw − rata-rata (counts)
A5: 1 | B5: 2704 | C5: =(A5-1)*0.25 -> 0 | D5: -39066 | E5: 0.003 | F5: 0.003 | G5: 0.001 | H5: STABLE | I5: =IF(D5="","",D5-AVERAGE($D$5:$D$244)) -> 31.445833
A6: 2 | B6: 2705 | C6: =(A6-1)*0.25 -> 0.25 | D6: -39105 | E6: 0.002 | F6: 0.003 | G6: 0.002 | H6: STABLE | I6: =IF(D6="","",D6-AVERAGE($D$5:$D$244)) -> -7.5541667
A7: 3 | B7: 2706 | C7: =(A7-1)*0.25 -> 0.5 | D7: -39112 | E7: 0.002 | F7: 0.003 | G7: 0.001 | H7: STABLE | I7: =IF(D7="","",D7-AVERAGE($D$5:$D$244)) -> -14.554167
A8: 4 | B8: 2707 | C8: =(A8-1)*0.25 -> 0.75 | D8: -39077 | E8: 0.003 | F8: 0.003 | G8: 0.001 | H8: STABLE | I8: =IF(D8="","",D8-AVERAGE($D$5:$D$244)) -> 20.445833
A9: 5 | B9: 2708 | C9: =(A9-1)*0.25 -> 1 | D9: -39102 | E9: 0.002 | F9: 0.003 | G9: 0.001 | H9: STABLE | I9: =IF(D9="","",D9-AVERAGE($D$5:$D$244)) -> -4.5541667
A10: 6 | B10: 2709 | C10: =(A10-1)*0.25 -> 1.25 | D10: -39047 | E10: 0.003 | F10: 0.003 | G10: 0.001 | H10: STABLE | I10: =IF(D10="","",D10-AVERAGE($D$5:$D$244)) -> 50.445833
A11: 7 | B11: 2710 | C11: =(A11-1)*0.25 -> 1.5 | D11: -39030 | E11: 0.004 | F11: 0.003 | G11: 0.001 | H11: STABLE | I11: =IF(D11="","",D11-AVERAGE($D$5:$D$244)) -> 67.445833
A12: 8 | B12: 2711 | C12: =(A12-1)*0.25 -> 1.75 | D12: -39155 | E12: 0.001 | F12: 0.003 | G12: 0.002 | H12: STABLE | I12: =IF(D12="","",D12-AVERAGE($D$5:$D$244)) -> -57.554167
A13: 9 | B13: 2712 | C13: =(A13-1)*0.25 -> 2 | D13: -39144 | E13: 0.002 | F13: 0.002 | G13: 0.001 | H13: STABLE | I13: =IF(D13="","",D13-AVERAGE($D$5:$D$244)) -> -46.554167
A14: 10 | B14: 2713 | C14: =(A14-1)*0.25 -> 2.25 | D14: -39090 | E14: 0.003 | F14: 0.002 | G14: 0.001 | H14: STABLE | I14: =IF(D14="","",D14-AVERAGE($D$5:$D$244)) -> 7.4458333
A15: 11 | B15: 2714 | C15: =(A15-1)*0.25 -> 2.5 | D15: -39105 | E15: 0.002 | F15: 0.002 | G15: 0.001 | H15: STABLE | I15: =IF(D15="","",D15-AVERAGE($D$5:$D$244)) -> -7.5541667
A16: 12 | B16: 2715 | C16: =(A16-1)*0.25 -> 2.75 | D16: -39103 | E16: 0.002 | F16: 0.002 | G16: 0 | H16: STABLE | I16: =IF(D16="","",D16-AVERAGE($D$5:$D$244)) -> -5.5541667
... A244: 240 | B244: 2943 | C244: =(A244-1)*0.25 -> 59.75 | D244: -39085 | E244: 0.003 | F244: 0.002 | G244: 0.001 | H244: STABLE | I244: =IF(D244="","",D244-AVERAGE($D$5:$D$244)) -> 12.445833

Sheet E1 15 Okt
A1: E1 ulang 15 Okt. 2026 (tanpa pemanasan)
A2: Baris yang dicetak sketsa uji_bench_hgd selama E1 (4 baris/s; sketsa menghitung σ dari semua sampel ≈ 11,8/s, jadi statistik dari baris ini sedikit berbeda dari ringkasan sketsa). Nilai biru = disalin dari log Serial Monitor. t perkiraan = (No − 1) × 0,25 s.
A4: No | B4: Baris log | C4: t perkiraan (s) | D4: raw (counts) | E4: kg (skala awal) | F4: win_avg (kg) | G4: spread (kg) | H4: Tanda | I4: raw − rata-rata (counts)
A5: 1 | B5: 130 | C5: =(A5-1)*0.25 -> 0 | D5: -39850 | E5: 0.001 | F5: 0.002 | G5: 0.001 | H5: STABLE | I5: =IF(D5="","",D5-AVERAGE($D$5:$D$244)) -> 60.970833
A6: 2 | B6: 131 | C6: =(A6-1)*0.25 -> 0.25 | D6: -39820 | E6: 0.002 | F6: 0.001 | G6: 0.001 | H6: STABLE | I6: =IF(D6="","",D6-AVERAGE($D$5:$D$244)) -> 90.970833
A7: 3 | B7: 132 | C7: =(A7-1)*0.25 -> 0.5 | D7: -39884 | E7: 0 | F7: 0.001 | G7: 0.001 | H7: STABLE | I7: =IF(D7="","",D7-AVERAGE($D$5:$D$244)) -> 26.970833
A8: 4 | B8: 133 | C8: =(A8-1)*0.25 -> 0.75 | D8: -39845 | E8: 0.001 | F8: 0.001 | G8: 0.001 | H8: STABLE | I8: =IF(D8="","",D8-AVERAGE($D$5:$D$244)) -> 65.970833
A9: 5 | B9: 134 | C9: =(A9-1)*0.25 -> 1 | D9: -39812 | E9: 0.002 | F9: 0.001 | G9: 0.001 | H9: STABLE | I9: =IF(D9="","",D9-AVERAGE($D$5:$D$244)) -> 98.970833
A10: 6 | B10: 135 | C10: =(A10-1)*0.25 -> 1.25 | D10: -39833 | E10: 0.001 | F10: 0.001 | G10: 0.001 | H10: STABLE | I10: =IF(D10="","",D10-AVERAGE($D$5:$D$244)) -> 77.970833
A11: 7 | B11: 136 | C11: =(A11-1)*0.25 -> 1.5 | D11: -39923 | E11: 0 | F11: 0 | G11: 0.002 | H11: STABLE | I11: =IF(D11="","",D11-AVERAGE($D$5:$D$244)) -> -12.029167
A12: 8 | B12: 137 | C12: =(A12-1)*0.25 -> 1.75 | D12: -39853 | E12: 0.001 | F12: 0 | G12: 0.001 | H12: STABLE | I12: =IF(D12="","",D12-AVERAGE($D$5:$D$244)) -> 57.970833
A13: 9 | B13: 138 | C13: =(A13-1)*0.25 -> 2 | D13: -39905 | E13: 0 | F13: 0.001 | G13: 0.001 | H13: STABLE | I13: =IF(D13="","",D13-AVERAGE($D$5:$D$244)) -> 5.9708333
A14: 10 | B14: 139 | C14: =(A14-1)*0.25 -> 2.25 | D14: -39951 | E14: -0.001 | F14: 0 | G14: 0.002 | H14: STABLE | I14: =IF(D14="","",D14-AVERAGE($D$5:$D$244)) -> -40.029167
A15: 11 | B15: 140 | C15: =(A15-1)*0.25 -> 2.5 | D15: -39855 | E15: 0.001 | F15: 0 | G15: 0.002 | H15: STABLE | I15: =IF(D15="","",D15-AVERAGE($D$5:$D$244)) -> 55.970833
A16: 12 | B16: 141 | C16: =(A16-1)*0.25 -> 2.75 | D16: -39881 | E16: 0 | F16: 0 | G16: 0.001 | H16: STABLE | I16: =IF(D16="","",D16-AVERAGE($D$5:$D$244)) -> 29.970833
... A244: 240 | B244: 369 | C244: =(A244-1)*0.25 -> 59.75 | D244: -39880 | E244: 0 | F244: 0 | G244: 0.001 | H244: STABLE | I244: =IF(D244="","",D244-AVERAGE($D$5:$D$244)) -> 30.970833

Sheet E1 rakitan akhir
A1: E1 rakitan akhir (isi setelah housing dirakit)
A2: Tempel baris raw=... dari Serial Monitor: isi kolom B-H (sel kuning). Kolom C dan I terhitung sendiri. Jalankan sesuai firmware/protokol-uji-bench-hgd.md (pemanasan ≥ 10 menit, lalu e).
A4: No | B4: Baris log | C4: t perkiraan (s) | D4: raw (counts) | E4: kg (skala awal) | F4: win_avg (kg) | G4: spread (kg) | H4: Tanda | I4: raw − rata-rata (counts)
A5: 1 | C5: =IF(D5="","",(A5-1)*0.25) | I5: =IF(D5="","",D5-AVERAGE($D$5:$D$304))
A6: 2 | C6: =IF(D6="","",(A6-1)*0.25) | I6: =IF(D6="","",D6-AVERAGE($D$5:$D$304))
A7: 3 | C7: =IF(D7="","",(A7-1)*0.25) | I7: =IF(D7="","",D7-AVERAGE($D$5:$D$304))
A8: 4 | C8: =IF(D8="","",(A8-1)*0.25) | I8: =IF(D8="","",D8-AVERAGE($D$5:$D$304))
A9: 5 | C9: =IF(D9="","",(A9-1)*0.25) | I9: =IF(D9="","",D9-AVERAGE($D$5:$D$304))
A10: 6 | C10: =IF(D10="","",(A10-1)*0.25) | I10: =IF(D10="","",D10-AVERAGE($D$5:$D$304))
A11: 7 | C11: =IF(D11="","",(A11-1)*0.25) | I11: =IF(D11="","",D11-AVERAGE($D$5:$D$304))
A12: 8 | C12: =IF(D12="","",(A12-1)*0.25) | I12: =IF(D12="","",D12-AVERAGE($D$5:$D$304))
A13: 9 | C13: =IF(D13="","",(A13-1)*0.25) | I13: =IF(D13="","",D13-AVERAGE($D$5:$D$304))
A14: 10 | C14: =IF(D14="","",(A14-1)*0.25) | I14: =IF(D14="","",D14-AVERAGE($D$5:$D$304))
A15: 11 | C15: =IF(D15="","",(A15-1)*0.25) | I15: =IF(D15="","",D15-AVERAGE($D$5:$D$304))
A16: 12 | C16: =IF(D16="","",(A16-1)*0.25) | I16: =IF(D16="","",D16-AVERAGE($D$5:$D$304))
... A304: 300 | C304: =IF(D304="","",(A304-1)*0.25) | I304: =IF(D304="","",D304-AVERAGE($D$5:$D$304))

Sheet Pemanasan 16 Okt
A1: Pemanasan 16 Okt. 2026 (sebelum E1)
A2: Baris sebelum E1 (pemanasan) 16 Okt. 2026; 4 baris/s. Baris serial rusak tidak dimasukkan (lihat Log mentah).
A4: No | B4: Baris log | C4: t perkiraan (s) | D4: raw (counts) | E4: kg (skala awal) | F4: win_avg (kg) | G4: spread (kg) | H4: Tanda | I4: raw − rata-rata (counts) | K4: Blok 75 s (300 baris) | L4: Rata-rata raw (counts) | M4: Selisih dari blok terakhir (counts)
A5: 1 | B5: 22 | C5: =(A5-1)*0.25 -> 0 | D5: -39186 | E5: -0.73 | F5: -0.73 | G5: 0 | I5: =IF(D5="","",D5-AVERAGE($D$5:$D$2677)) -> -105.94388 | K5: 0-75 s | L5: =AVERAGE(D5:D304) -> -39134.047 | M5: =L5-$L$13 -> -74.325055
A6: 2 | B6: 23 | C6: =(A6-1)*0.25 -> 0.25 | D6: -39246 | E6: -0.731 | F6: -0.731 | G6: 0.002 | I6: =IF(D6="","",D6-AVERAGE($D$5:$D$2677)) -> -165.94388 | K6: 75-150 s | L6: =AVERAGE(D305:D604) -> -39090.737 | M6: =L6-$L$13 -> -31.015055
A7: 3 | B7: 24 | C7: =(A7-1)*0.25 -> 0.5 | D7: -39216 | E7: -0.73 | F7: -0.731 | G7: 0.001 | H7: STABLE | I7: =IF(D7="","",D7-AVERAGE($D$5:$D$2677)) -> -135.94388 | K7: 150-225 s | L7: =AVERAGE(D605:D904) -> -39079.507 | M7: =L7-$L$13 -> -19.785055
A8: 4 | B8: 26 | C8: =(A8-1)*0.25 -> 0.75 | D8: -39243 | E8: -0.731 | F8: 0 | G8: 0 | I8: =IF(D8="","",D8-AVERAGE($D$5:$D$2677)) -> -162.94388 | K8: 225-300 s | L8: =AVERAGE(D905:D1204) -> -39060.723 | M8: =L8-$L$13 -> -1.0017216
A9: 5 | B9: 27 | C9: =(A9-1)*0.25 -> 1 | D9: -39168 | E9: 0.001 | F9: 0 | G9: 0.002 | I9: =IF(D9="","",D9-AVERAGE($D$5:$D$2677)) -> -87.943883 | K9: 300-375 s | L9: =AVERAGE(D1205:D1504) -> -39050.723 | M9: =L9-$L$13 -> 8.9982784
A10: 6 | B10: 28 | C10: =(A10-1)*0.25 -> 1.25 | D10: -39210 | E10: 0 | F10: 0.001 | G10: 0.001 | H10: STABLE | I10: =IF(D10="","",D10-AVERAGE($D$5:$D$2677)) -> -129.94388 | K10: 375-450 s | L10: =AVERAGE(D1505:D1804) -> -39084.627 | M10: =L10-$L$13 -> -24.905055
A11: 7 | B11: 29 | C11: =(A11-1)*0.25 -> 1.5 | D11: -39176 | E11: 0.001 | F11: 0.001 | G11: 0.001 | H11: STABLE | I11: =IF(D11="","",D11-AVERAGE($D$5:$D$2677)) -> -95.943883 | K11: 450-525 s | L11: =AVERAGE(D1805:D2104) -> -39091.74 | M11: =L11-$L$13 -> -32.018388
A12: 8 | B12: 30 | C12: =(A12-1)*0.25 -> 1.75 | D12: -39230 | E12: 0 | F12: 0 | G12: 0.002 | H12: STABLE | I12: =IF(D12="","",D12-AVERAGE($D$5:$D$2677)) -> -149.94388 | K12: 525-600 s | L12: =AVERAGE(D2105:D2404) -> -39066.85 | M12: =L12-$L$13 -> -7.1283883
A13: 9 | B13: 31 | C13: =(A13-1)*0.25 -> 2 | D13: -39257 | E13: 0 | F13: 0 | G13: 0.002 | H13: STABLE | I13: =IF(D13="","",D13-AVERAGE($D$5:$D$2677)) -> -176.94388 | K13: 600-668 s | L13: =AVERAGE(D2405:D2677) -> -39059.722 | M13: =L13-$L$13 -> 0
A14: 10 | B14: 32 | C14: =(A14-1)*0.25 -> 2.25 | D14: -39261 | E14: -0.001 | F14: 0 | G14: 0.001 | H14: STABLE | I14: =IF(D14="","",D14-AVERAGE($D$5:$D$2677)) -> -180.94388
A15: 11 | B15: 33 | C15: =(A15-1)*0.25 -> 2.5 | D15: -39202 | E15: 0.001 | F15: 0 | G15: 0.001 | H15: STABLE | I15: =IF(D15="","",D15-AVERAGE($D$5:$D$2677)) -> -121.94388
A16: 12 | B16: 34 | C16: =(A16-1)*0.25 -> 2.75 | D16: -39179 | E16: 0.001 | F16: 0.001 | G16: 0.002 | H16: STABLE | I16: =IF(D16="","",D16-AVERAGE($D$5:$D$2677)) -> -98.943883
A17: 13 | B17: 35 | C17: =(A17-1)*0.25 -> 3 | D17: -39183 | E17: 0.001 | F17: 0.001 | G17: 0.001 | H17: STABLE | I17: =IF(D17="","",D17-AVERAGE($D$5:$D$2677)) -> -102.94388
A18: 14 | B18: 36 | C18: =(A18-1)*0.25 -> 3.25 | D18: -39163 | E18: 0.001 | F18: 0.001 | G18: 0.001 | H18: STABLE | I18: =IF(D18="","",D18-AVERAGE($D$5:$D$2677)) -> -82.943883
A19: 15 | B19: 37 | C19: =(A19-1)*0.25 -> 3.5 | D19: -39225 | E19: 0 | F19: 0.001 | G19: 0.001 | H19: STABLE | I19: =IF(D19="","",D19-AVERAGE($D$5:$D$2677)) -> -144.94388
A20: 16 | B20: 38 | C20: =(A20-1)*0.25 -> 3.75 | D20: -39178 | E20: 0.001 | F20: 0 | G20: 0.001 | H20: STABLE | I20: =IF(D20="","",D20-AVERAGE($D$5:$D$2677)) -> -97.943883
A21: 17 | B21: 39 | C21: =(A21-1)*0.25 -> 4 | D21: -39246 | E21: 0 | F21: 0.001 | G21: 0.002 | H21: STABLE | I21: =IF(D21="","",D21-AVERAGE($D$5:$D$2677)) -> -165.94388
A22: 18 | B22: 40 | C22: =(A22-1)*0.25 -> 4.25 | D22: -39182 | E22: 0.001 | F22: 0 | G22: 0.001 | H22: STABLE | I22: =IF(D22="","",D22-AVERAGE($D$5:$D$2677)) -> -101.94388
A23: 19 | B23: 41 | C23: =(A23-1)*0.25 -> 4.5 | D23: -39253 | E23: 0 | F23: 0 | G23: 0.001 | H23: STABLE | I23: =IF(D23="","",D23-AVERAGE($D$5:$D$2677)) -> -172.94388
A24: 20 | B24: 42 | C24: =(A24-1)*0.25 -> 4.75 | D24: -39267 | E24: -0.001 | F24: 0 | G24: 0.001 | H24: STABLE | I24: =IF(D24="","",D24-AVERAGE($D$5:$D$2677)) -> -186.94388
A25: 21 | B25: 43 | C25: =(A25-1)*0.25 -> 5 | D25: -39234 | E25: 0 | F25: 0 | G25: 0.001 | H25: STABLE | I25: =IF(D25="","",D25-AVERAGE($D$5:$D$2677)) -> -153.94388
... A2677: 2673 | B2677: 2702 | C2677: =(A2677-1)*0.25 -> 668 | D2677: -39094 | E2677: 0.003 | F2677: 0.002 | G2677: 0.001 | H2677: STABLE | I2677: =IF(D2677="","",D2677-AVERAGE($D$5:$D$2677)) -> -13.943883

Sheet Uji tekan 16 Okt
A1: Setelah E1 16 Okt. 2026: uji arah tekan, tombol, tare ulang
A2: Baris setelah E1. Tekan 1 dan 2 ≈ 2,5-2,9 kg, tekan 3 ≈ 3,1 kg ditahan ≈ 9 s (skala awal 53.687 counts/kg, belum dikalibrasi).
A4: No | B4: Baris log | C4: t perkiraan (s) | D4: raw (counts) | E4: kg (skala awal) | F4: win_avg (kg) | G4: spread (kg) | H4: Tanda | I4: raw − rata-rata (counts)
A5: 1 | B5: 2948 | C5: =(A5-1)*0.25 -> 0 | D5: -39136 | E5: 0.002 | F5: 0.002 | G5: 0.001 | H5: STABLE | I5: =IF(D5="","",D5-AVERAGE($D$5:$D$722)) -> -14475.116
A6: 2 | B6: 2949 | C6: =(A6-1)*0.25 -> 0.25 | D6: -39178 | E6: 0.001 | F6: 0.002 | G6: 0.001 | H6: STABLE | I6: =IF(D6="","",D6-AVERAGE($D$5:$D$722)) -> -14517.116
A7: 3 | B7: 2950 | C7: =(A7-1)*0.25 -> 0.5 | D7: -39141 | E7: 0.002 | F7: 0.001 | G7: 0.001 | H7: STABLE | I7: =IF(D7="","",D7-AVERAGE($D$5:$D$722)) -> -14480.116
A8: 4 | B8: 2951 | C8: =(A8-1)*0.25 -> 0.75 | D8: -39153 | E8: 0.002 | F8: 0.002 | G8: 0 | H8: STABLE | I8: =IF(D8="","",D8-AVERAGE($D$5:$D$722)) -> -14492.116
A9: 5 | B9: 2952 | C9: =(A9-1)*0.25 -> 1 | D9: -39118 | E9: 0.002 | F9: 0.001 | G9: 0.002 | H9: STABLE | I9: =IF(D9="","",D9-AVERAGE($D$5:$D$722)) -> -14457.116
A10: 6 | B10: 2953 | C10: =(A10-1)*0.25 -> 1.25 | D10: -39133 | E10: 0.002 | F10: 0.002 | G10: 0.001 | H10: STABLE | I10: =IF(D10="","",D10-AVERAGE($D$5:$D$722)) -> -14472.116
A11: 7 | B11: 2954 | C11: =(A11-1)*0.25 -> 1.5 | D11: -39184 | E11: 0.001 | F11: 0.001 | G11: 0.001 | H11: STABLE | I11: =IF(D11="","",D11-AVERAGE($D$5:$D$722)) -> -14523.116
A12: 8 | B12: 2955 | C12: =(A12-1)*0.25 -> 1.75 | D12: -39161 | E12: 0.001 | F12: 0.001 | G12: 0.001 | H12: STABLE | I12: =IF(D12="","",D12-AVERAGE($D$5:$D$722)) -> -14500.116
A13: 9 | B13: 2956 | C13: =(A13-1)*0.25 -> 2 | D13: -39141 | E13: 0.002 | F13: 0.002 | G13: 0.002 | H13: STABLE | I13: =IF(D13="","",D13-AVERAGE($D$5:$D$722)) -> -14480.116
A14: 10 | B14: 2957 | C14: =(A14-1)*0.25 -> 2.25 | D14: -39145 | E14: 0.002 | F14: 0.002 | G14: 0.001 | H14: STABLE | I14: =IF(D14="","",D14-AVERAGE($D$5:$D$722)) -> -14484.116
A15: 11 | B15: 2958 | C15: =(A15-1)*0.25 -> 2.5 | D15: -39142 | E15: 0.002 | F15: 0.001 | G15: 0.001 | H15: STABLE | I15: =IF(D15="","",D15-AVERAGE($D$5:$D$722)) -> -14481.116
A16: 12 | B16: 2959 | C16: =(A16-1)*0.25 -> 2.75 | D16: -39134 | E16: 0.002 | F16: 0.002 | G16: 0 | H16: STABLE | I16: =IF(D16="","",D16-AVERAGE($D$5:$D$722)) -> -14473.116
... A108: 104 | B108: 3051 | C108: =(A108-1)*0.25 -> 25.75 | D108: -18411 | E108: 0.388 | F108: 0.232 | G108: 0.254 | H108: STABLE | I108: =IF(D108="","",D108-AVERAGE($D$5:$D$722)) -> 6249.8844
A109: 105 | B109: 3052 | C109: =(A109-1)*0.25 -> 26 | D109: 9995 | E109: 0.917 | F109: 0.566 | G109: 0.636 | I109: =IF(D109="","",D109-AVERAGE($D$5:$D$722)) -> 34655.884
A110: 106 | B110: 3053 | C110: =(A110-1)*0.25 -> 26.25 | D110: 44760 | E110: 1.565 | F110: 1.143 | G110: 0.857 | I110: =IF(D110="","",D110-AVERAGE($D$5:$D$722)) -> 69420.884
A111: 107 | B111: 3054 | C111: =(A111-1)*0.25 -> 26.5 | D111: 71122 | E111: 2.056 | F111: 1.738 | G111: 0.68 | I111: =IF(D111="","",D111-AVERAGE($D$5:$D$722)) -> 95782.884
A112: 108 | B112: 3055 | C112: =(A112-1)*0.25 -> 26.75 | D112: 76503 | E112: 2.156 | F112: 2.002 | G112: 0.404 | H112: STABLE | I112: =IF(D112="","",D112-AVERAGE($D$5:$D$722)) -> 101163.88
A113: 109 | B113: 3056 | C113: =(A113-1)*0.25 -> 27 | D113: 87173 | E113: 2.355 | F113: 2.224 | G113: 0.252 | H113: STABLE | I113: =IF(D113="","",D113-AVERAGE($D$5:$D$722)) -> 111833.88
A114: 110 | B114: 3057 | C114: =(A114-1)*0.25 -> 27.25 | D114: 96651 | E114: 2.531 | F114: 2.417 | G114: 0.245 | H114: STABLE | I114: =IF(D114="","",D114-AVERAGE($D$5:$D$722)) -> 121311.88
A115: 111 | B115: 3058 | C115: =(A115-1)*0.25 -> 27.5 | D115: 107106 | E115: 2.726 | F115: 2.597 | G115: 0.237 | H115: STABLE | I115: =IF(D115="","",D115-AVERAGE($D$5:$D$722)) -> 131766.88
A116: 112 | B116: 3059 | C116: =(A116-1)*0.25 -> 27.75 | D116: 97048 | E116: 2.538 | F116: 2.669 | G116: 0.198 | H116: STABLE | I116: =IF(D116="","",D116-AVERAGE($D$5:$D$722)) -> 121708.88
A117: 113 | B117: 3060 | C117: =(A117-1)*0.25 -> 28 | D117: 86724 | E117: 2.346 | F117: 2.453 | G117: 0.369 | H117: STABLE | I117: =IF(D117="","",D117-AVERAGE($D$5:$D$722)) -> 111384.88
A118: 114 | B118: 3061 | C118: =(A118-1)*0.25 -> 28.25 | D118: 95551 | E118: 2.511 | F118: 2.413 | G118: 0.194 | H118: STABLE | I118: =IF(D118="","",D118-AVERAGE($D$5:$D$722)) -> 120211.88
A119: 115 | B119: 3062 | C119: =(A119-1)*0.25 -> 28.5 | D119: 99224 | E119: 2.579 | F119: 2.522 | G119: 0.102 | H119: STABLE | I119: =IF(D119="","",D119-AVERAGE($D$5:$D$722)) -> 123884.88
A120: 116 | B120: 3063 | C120: =(A120-1)*0.25 -> 28.75 | D120: 110044 | E120: 2.781 | F120: 2.656 | G120: 0.248 | H120: STABLE | I120: =IF(D120="","",D120-AVERAGE($D$5:$D$722)) -> 134704.88
A121: 117 | B121: 3064 | C121: =(A121-1)*0.25 -> 29 | D121: 116869 | E121: 2.908 | F121: 2.82 | G121: 0.174 | H121: STABLE | I121: =IF(D121="","",D121-AVERAGE($D$5:$D$722)) -> 141529.88
A122: 118 | B122: 3065 | C122: =(A122-1)*0.25 -> 29.25 | D122: 114349 | E122: 2.861 | F122: 2.896 | G122: 0.071 | H122: STABLE | I122: =IF(D122="","",D122-AVERAGE($D$5:$D$722)) -> 139009.88
A123: 119 | B123: 3066 | C123: =(A123-1)*0.25 -> 29.5 | D123: 106164 | E123: 2.708 | F123: 2.802 | G123: 0.208 | H123: STABLE | I123: =IF(D123="","",D123-AVERAGE($D$5:$D$722)) -> 130824.88
... A125: 121 | B125: 3068 | C125: =(A125-1)*0.25 -> 30 | D125: 100715 | E125: 2.607 | F125: 2.655 | G125: 0.107 | H125: STABLE | I125: =IF(D125="","",D125-AVERAGE($D$5:$D$722)) -> 125375.88
A126: 122 | B126: 3069 | C126: =(A126-1)*0.25 -> 30.25 | D126: 73643 | E126: 2.103 | F126: 2.467 | G126: 0.511 | I126: =IF(D126="","",D126-AVERAGE($D$5:$D$722)) -> 98303.884
A127: 123 | B127: 3070 | C127: =(A127-1)*0.25 -> 30.5 | D127: 31249 | E127: 1.313 | F127: 1.856 | G127: 1.112 | I127: =IF(D127="","",D127-AVERAGE($D$5:$D$722)) -> 55909.884
A128: 124 | B128: 3071 | C128: =(A128-1)*0.25 -> 30.75 | D128: -7272 | E128: 0.595 | F128: 1.26 | G128: 1.24 | I128: =IF(D128="","",D128-AVERAGE($D$5:$D$722)) -> 17388.884
A129: 125 | B129: 3072 | C129: =(A129-1)*0.25 -> 31 | D129: -32105 | E129: 0.133 | F129: 0.446 | G129: 0.821 | I129: =IF(D129="","",D129-AVERAGE($D$5:$D$722)) -> -7444.1156
A130: 126 | B130: 3073 | C130: =(A130-1)*0.25 -> 31.25 | D130: -31842 | E130: 0.138 | F130: 0.157 | G130: 0.068 | H130: STABLE | I130: =IF(D130="","",D130-AVERAGE($D$5:$D$722)) -> -7181.1156
A131: 127 | B131: 3074 | C131: =(A131-1)*0.25 -> 31.5 | D131: -31777 | E131: 0.139 | F131: 0.147 | G131: 0.035 | H131: STABLE | I131: =IF(D131="","",D131-AVERAGE($D$5:$D$722)) -> -7116.1156
A132: 128 | B132: 3075 | C132: =(A132-1)*0.25 -> 31.75 | D132: -32230 | E132: 0.13 | F132: 0.139 | G132: 0.015 | H132: STABLE | I132: =IF(D132="","",D132-AVERAGE($D$5:$D$722)) -> -7569.1156
A133: 129 | B133: 3076 | C133: =(A133-1)*0.25 -> 32 | D133: -34897 | E133: 0.081 | F133: 0.115 | G133: 0.059 | H133: STABLE | I133: =IF(D133="","",D133-AVERAGE($D$5:$D$722)) -> -10236.116
...

Sheet Log mentah 16 Okt
A1: Baris | B1: Teks log Serial Monitor (apa adanya)
A2: 1 | B2: ets Jul 29 2019 12:21:46
A3: 2
A4: 3 | B4: rst:0x1 (POWERON_RESET),boot:0x13 (SPI_FAST_FLASH_BOOT)
A5: 4 | B5: configsip: 0, SPIWP:0xee
A6: 5 | B6: clk_drv:0x00,q_drv:0x00,d_drv:0x00,cs0_drv:0x00,hd_drv:0x00,wp_drv:0x00
A7: 6 | B7: mode:DIO, clock div:1
A8: 7 | B8: load:0x3fff0030,len:4640
A9: 8 | B9: load:0x40078000,len:15592
A10: 9 | B10: load:0x40080400,len:3164
A11: 10 | B11: entry 0x4008059c
A12: 11
A13: 12 | B13: === HGD bench test ===
A14: 13 | B14: I2C scan (SDA=21, SCL=22):
A15: 14 | B15: found 0x27
A16: 15 | B16: LCD ready at 0x27
A17: 16 | B17: HX711: DT went low, module responds.
A18: 17 | B18: Note: with the load cell not connected the HX711 inputs float and readings are meaningless.
A19: 18
A20: 19 | B20: Commands: t tare | k avg of 10 raw | p print state | e 60 s noise test (E1)
A21: 20 | B21: n flip sign | l toggle LED | s I2C scan | h help
A22: 21 | B22: Button: TAP toggles the LED, HOLD 1.5 s re-tares
A23: 22 | B23: raw=-39186 kg=-0.730 win_avg=-0.730 spread=0.000
A24: 23 | B24: raw=-39246 kg=-0.731 win_avg=-0.731 spread=0.002
A25: 24 | B25: raw=-39216 kg=-0.730 win_avg=-0.731 spread=0.001 STABLE
A26: 25 | B26: [TARE] offset=-39234 counts (avg of 10 samples, spread 104 counts)
A27: 26 | B27: raw=-39243 kg=-0.731 win_avg=+0.000 spread=0.000
A28: 27 | B28: raw=-39168 kg=+0.001 win_avg=+0.000 spread=0.002
A29: 28 | B29: raw=-39210 kg=+0.000 win_avg=+0.001 spread=0.001 STABLE
A30: 29 | B30: raw=-39176 kg=+0.001 win_avg=+0.001 spread=0.001 STABLE
A31: 30 | B31: raw=-39230 kg=+0.000 win_avg=+0.000 spread=0.002 STABLE
... A3679: 3678 | B3679: raw=-39047 kg=-0.001 win_avg=-0.001 spread=0.001 STABLE

Sheet Log mentah 15 Okt
A1: Baris | B1: Teks log Serial Monitor (apa adanya)
A2: 1 | B2: ets Jul 29 2019 12:21:46
A3: 2
A4: 3 | B4: rst:0x1 (POWERON_RESET),boot:0x13 (SPI_FAST_FLASH_BOOT)
A5: 4 | B5: configsip: 0, SPIWP:0xee
A6: 5 | B6: clk_drv:0x00,q_drv:0x00,d_drv:0x00,cs0_drv:0x00,hd_drv:0x00,wp_drv:0x00
A7: 6 | B7: mode:DIO, clock div:1
A8: 7 | B8: load:0x3fff0030,len:4640
A9: 8 | B9: load:0x40078000,len:15592
A10: 9 | B10: load:0x40080400,len:3164
A11: 10 | B11: entry 0x4008059c
A12: 11
A13: 12 | B13: === HGD bench test ===
A14: 13 | B14: I2C scan (SDA=21, SCL=22):
A15: 14 | B15: found 0x27
A16: 15 | B16: LCD ready at 0x27
A17: 16 | B17: HX711: DT went low, module responds.
A18: 17 | B18: Note: with the load cell not connected the HX711 inputs float and readings are meaningless.
A19: 18
A20: 19 | B20: Commands: t tare | k avg of 10 raw | p print state | e 60 s noise test (E1)
A21: 20 | B21: n flip sign | l toggle LED | s I2C scan | h help
A22: 21 | B22: Button: TAP toggles the LED, HOLD 1.5 s re-tares
A23: 22 | B23: raw=-39889 kg=-0.743 win_avg=-0.743 spread=0.000
A24: 23 | B24: raw=-39918 kg=-0.744 win_avg=-0.743 spread=0.001
A25: 24 | B25: raw=-39893 kg=-0.743 win_avg=-0.743 spread=0.001 STABLE
A26: 25 | B26: [TARE] offset=-39904 counts (avg of 10 samples, spread 48 counts)
A27: 26 | B27: raw=-39914 kg=-0.743 win_avg=+0.000 spread=0.000
A28: 27 | B28: raw=-39854 kg=+0.001 win_avg=+0.000 spread=0.001
A29: 28 | B29: raw=-39936 kg=-0.001 win_avg=+0.000 spread=0.002 STABLE
A30: 29 | B30: raw=-39862 kg=+0.001 win_avg=-0.000 spread=0.001 STABLE
A31: 30 | B31: raw=-39935 kg=-0.001 win_avg=+0.000 spread=0.002 STABLE
... A402: 401 | B402: raw=-39872 kg=+0.001 win_avg=+0.000 spread=0.002 STABLE
