Workbook

Sheet Mekanik
A1: Perhitungan mekanik: kekakuan pelat, tegangan, celah, spacer, baut, dan massa (housing grip)
A2: Legenda: sel BIRU dengan latar KUNING = input yang boleh diubah; HIJAU = tautan ke blok Elektrik; HITAM = rumus. Model: kantilever, spacer dan baut dianggap kaku; lenturan load cell, tinggi penutup, dan margin rakit ada di anggaran celah. Ini hitungan kasar untuk arah desain, bukan verifikasi.
A3: 1. Input geometri dan bahan
A4: Besaran | B4: Nilai | C4: Satuan | D4: Rumus / arti / catatan | E4: Referensi
A5: Beban rancangan (genggam maksimum) | B5: =Elektrik!$B$8 -> 70 | C5: kgf | D5: Tautan ke Input Elektrik (beban maksimum yang dipakai) | E5: Blok Elektrik, Input
A6: Percepatan gravitasi | B6: =Elektrik!$B$30 -> 9.80665 | C6: m/s^2 | D6: Tautan ke Input Elektrik | E6: Konstanta standar
A7: Lebar pelat A dan B (b) | B7: 30 | C7: mm | D7: Pelat aluminium polos | E7: housing-load-cell/asumsi.md Bagian 2
A8: Tebal pelat (h) | B8: 10 | C8: mm | D8: Al 6061-T6 (nilai keputusan) | E8: asumsi.md Bagian 2; HL9
A9: Panjang pelat | B9: 170 | C9: mm | D9: Dipotong dari pelat 170 x 30 x 10 | E9: asumsi.md Bagian 2
A10: Modulus elastisitas aluminium (E) | B10: 70000 | C10: MPa | D10: 70 GPa dipakai di seluruh perhitungan; belum ada datasheet pemasok | E10: DS-MAT1 (belum diambil); asumsi.md Bagian 2
A11: Kuat luluh minimum Al 6061-T6 | B11: 240 | C11: MPa | D11: Nilai minimum yang dipakai untuk faktor keamanan | E11: asumsi.md Bagian 2; DS-MAT1 (belum diambil)
A12: Massa jenis aluminium | B12: 2700 | C12: kg/m^3 | D12: Nilai umum Al 6061 | E12: DS-MAT1 (belum diambil)
A13: Panjang load cell | B13: 130 | C13: mm | D13: Terukur 10 Okt. 2026 (gambar penjual 130) | E13: tabel-pengukuran-hgd.xlsx tab Load cell (C1); DS-LC1
A14: Tinggi load cell | B14: 21.5 | C14: mm | D14: Terukur 10 Okt. 2026 (gambar penjual 22) | E14: tabel-pengukuran-hgd.xlsx tab Load cell (C1); DS-LC1
A15: Panjang blok ujung load cell (boss_L) | B15: 28 | C15: mm | D15: Taksiran dari gambar penjual; ukur dengan jangka sorong | E15: tabel-pengukuran-hgd.xlsx tab Load cell (C4); DS-LC1
A16: Diameter lubang lewat di pelat | B16: 6.6 | C16: mm | D16: Lubang lewat M6 seri sedang | E16: ISO 273; asumsi.md Bagian 2.4
A17: Celah pelat ke badan load cell | B17: 2.5 | C17: mm | D17: Celah bebas-sentuh | E17: asumsi.md Bagian 2.2
A18: Tinggi ridge dan bidang tumpu | B18: 5 | C18: mm | D18: Di sisi luar B | E18: asumsi.md Bagian 3.3
A19: 2. Geometri turunan dan kekakuan pelat (kantilever)
A20: Besaran | B20: Nilai | C20: Satuan | D20: Rumus / arti / catatan | E20: Referensi
A21: Lengan tuas a | B21: =$B$13/2-$B$15 -> 37 | C21: mm | D21: a = L_lc/2 - boss_L | E21: asumsi.md Bagian 2 (Model)
A22: Jarak ujung jauh x | B22: =$B$13-$B$15 -> 102 | C22: mm | D22: x = L_lc - boss_L | E22: asumsi.md Bagian 2 (Model)
A23: Bentang bebas | B23: =$B$13-2*$B$15 -> 74 | C23: mm | D23: L_lc - 2 x boss_L | E23: asumsi.md Bagian 2
A24: Gaya rancangan F | B24: =$B$5*$B$6 -> 686.4655 | C24: N | D24: F = kgf x g (kgf dianggap sama dengan kg-massa) | E24: asumsi.md Bagian 2
A25: Momen inersia penampang pelat I | B25: =$B$7*$B$8^3/12 -> 2500 | C25: mm^4 | D25: I = b h^3 / 12 | E25: asumsi.md Bagian 2
A26: Lenturan di titik beban, delta(a) | B26: =$B$24*$B$21^3/(3*$B$10*$B$25) -> 0.066231499 | C26: mm | D26: delta(a) = F a^3 / (3 E I) | E26: asumsi.md Bagian 2; HL9
A27: Lenturan di ujung jauh, delta(x) | B27: =$B$24*$B$21^2*(3*$B$22-$B$21)/(6*$B$10*$B$25) -> 0.24076045 | C27: mm | D27: delta(x) = F a^2 (3x - a) / (6 E I) | E27: asumsi.md Bagian 2; HL9
A28: Tegangan lentur di pangkal, sigma | B28: =$B$24*$B$21*($B$8/2)/$B$25 -> 50.798447 | C28: MPa | D28: sigma = F a (h/2) / I | E28: asumsi.md Bagian 2
A29: Tegangan bersih di lubang, sigma_net | B29: =$B$28*$B$7/($B$7-2*$B$16) -> 90.711512 | C29: MPa | D29: sigma_net = sigma x b / (b - 2d); konservatif | E29: asumsi.md Bagian 2
A30: Faktor keamanan terhadap luluh | B30: =$B$11/$B$29 -> 2.6457502 | C30: x | D30: Kuat luluh / sigma_net | E30: asumsi.md Bagian 2
A31: 3. Anggaran celah
A32: Besaran | B32: Nilai | C32: Satuan | D32: Rumus / arti / catatan | E32: Referensi
A33: Lenturan load cell sendiri pada beban rancangan | B33: 0.5 | C33: mm | D33: Asumsi desain; belum diukur | E33: asumsi.md Bagian 2.3
A34: Tinggi penutup / area tengah di atas permukaan | B34: 1 | C34: mm | D34: Asumsi desain | E34: asumsi.md Bagian 2.3
A35: Margin rakit (kerataan pelat, spacer, baut) | B35: 0.3 | C35: mm | D35: Asumsi desain | E35: asumsi.md Bagian 2.3
A36: Total celah terpakai | B36: =$B$27+$B$33+$B$34+$B$35 -> 2.0407604 | C36: mm | D36: Lenturan ujung jauh + tiga butir di atas | E36: asumsi.md Bagian 2.3
A37: Sisa celah | B37: =$B$17-$B$36 -> 0.45923955 | C37: mm | D37: Harus positif | E37: asumsi.md Bagian 2.3
A38: Status celah | B38: =IF($B$37>0,"AMAN","CELAH TERLAMPAUI") -> AMAN | C38: -
A39: 4. Spacer PLA dan baut
A40: Besaran | B40: Nilai | C40: Satuan | D40: Rumus / arti / catatan | E40: Referensi
...

Sheet Elektrik
A1: Perhitungan elektrik: sinyal, ADC, noise, galat, dan kalibrasi (hand grip dynamometer, CZL 601 80 kg + HX711)
A3: Input parameter - Hand grip dynamometer (CZL 601 80 kg + HX711)
A4: Legenda: sel BIRU dengan latar KUNING = input yang boleh diubah. Blok Hitung, Galat, dan Kalibrasi di bawahnya berisi rumus dan ikut berubah. Sumber: DS-LC1 dan DS-HX1 di datasheet/datasheet-library.md ([4]-[6] load cell, [2] Avia).
A5: Parameter | B5: Nilai | C5: Satuan | D5: Sumber / catatan | E5: Referensi (nomor di datasheet/datasheet-library.md)
A6: Sensitivitas load cell (S) | B6: 2 | C6: mV/V | D6: Eagle Weigh [5]: 2,0 +-0,15 mV/V; nominal | E6: [5] Eagle Weigh (DS-LC1)
A7: Kapasitas load cell | B7: 80 | C7: kg | D7: Eagle Weigh [5] | E7: [5] Eagle Weigh (DS-LC1)
A8: Beban maksimum yang dipakai | B8: 70 | C8: kgf | D8: Asumsi proyek: pria muda maks sekitar 59 kgf (Gotthelf) + margin | E8: Gotthelf dkk. 2021 (sitasi/sitasi-hgd.md, kode G)
A9: Beban genggam tipikal (untuk % galat) | B9: 30 | C9: kgf | D9: Wanita 20-24 th rata-rata 31,7 kgf (Gotthelf) | E9: Gotthelf dkk. 2021 (sitasi/sitasi-hgd.md, kode G)
A10: Resistansi masukan jembatan | B10: 400 | C10: ohm | D10: GJ Impex [6]: 400 +-10; vendor 401 +-10; ukur saat tiba | E10: [6] GJ Impex; vendor [4] (DS-LC1)
A11: Tegangan eksitasi E+ (V_exc) | B11: 5 | C11: V | D11: Ukur di papan. Papan cacat: sekitar 4,3 V pada catu 5 V; catu 3,3 V: isi 3,3 | E11: Ukur di papan; DS-HX1 Peringatan
A12: AVDD HX711 | B12: 5 | C12: V | D12: Ukur; harus sama dengan catu modul | E12: [2] Avia (AVDD 2,6-5,5 V) (DS-HX1)
A13: Gain kanal A | B13: 128 | C13: - | D13: Avia [2]: 128 atau 64 | E13: [2] Avia (DS-HX1)
A14: Noise masukan 10 SPS | B14: 50 | C14: nV rms | D14: Avia [2], gain 128 | E14: [2] Avia (DS-HX1)
A15: Noise masukan 80 SPS | B15: 90 | C15: nV rms | D15: Avia [2], gain 128 | E15: [2] Avia (DS-HX1)
A16: Laju data terpilih | B16: 10 | C16: SPS | D16: 10 (bawaan papan) atau 80 | E16: [2] Avia (DS-HX1)
A17: Lebar kode ADC | B17: 24 | C17: bit | D17: Avia [2] | E17: [2] Avia (DS-HX1)
... A34: Jumlah pembacaan awal dibuang | B34: 4 | C34: sampel | D34: Settling 400 ms pada 10 Hz | E34: Asumsi
A37: Perhitungan utama (semua rumus; ubah nilai di blok Input (baris 3 sampai 34))
A38: Besaran | B38: Nilai | C38: Satuan | D38: Rumus / arti | E38: Referensi
A39: 1. Sinyal jembatan
A40: Keluaran jembatan pada skala penuh | B40: =$B$6*$B$11 -> 10 | C40: mV | D40: S x V_exc | E40: [5]; rumus ratiometrik jembatan
A41: Keluaran pada beban maksimum | B41: =B40*$B$8/$B$7 -> 8.75 | C41: mV | D41: S x V_exc x F/F_rated (kgf dianggap sama dengan kg) | E41: [5]
A42: Sensitivitas absolut | B42: =B40*1000000/($B$7*1000) -> 125 | C42: nV/g | D42: Pengubah noise ke gram | E42: [5]
A43: 2. Rentang ADC
A44: Skala penuh ADC (+-) | B44: =1000*0.5*$B$12/$B$13 -> 19.53125 | C44: mV | D44: 0,5 x AVDD / gain | E44: [2] Avia: skala penuh = 0,5 x AVDD / gain
A45: Pemakaian rentang pada kapasitas penuh | B45: =B40/B44 -> 0.512 | C45: - | D45: Saturasi jika > 1 | E45: [2]
A46: Pemakaian rentang pada beban maksimum | B46: =B41/B44 -> 0.448 | C46: - | E46: [2]
A47: Pemakaian pada overload aman | B47: =B45*$B$20/100 -> 0.6144 | C47: - | E47: [2]
A48: Pemakaian pada overload destruktif | B48: =B45*$B$21/100 -> 0.768 | C48: - | E48: [2]
A49: Status saturasi | B49: =IF(B48<1,"AMAN","SATURASI") -> AMAN | C49: - | D49: Pada overload destruktif | E49: [2]
A50: 3. Common-mode
A51: Titik tengah jembatan | B51: =$B$11/2 -> 2.5 | C51: V | D51: Perkiraan: E+/2 | E51: [2] Avia: kisaran common-mode
A52: Batas bawah | B52: =$B$18 -> 1.2 | C52: V | D52: AGND + 1,2 | E52: [2] Avia
A53: Batas atas | B53: =$B$12-$B$19 -> 3.7 | C53: V | D53: AVDD - 1,3 | E53: [2] Avia
A54: Status | B54: =IF(AND(B51>=B52,B51<=B53),"LULUS","CEK") -> LULUS | C54: - | E54: [2]
A55: 4. Hitungan ADC (counts)
A56: Hitungan pada kapasitas penuh | B56: =B45*2^($B$17-1) -> 4294967.3 | C56: count | D56: Pemakaian x 2^23 | E56: [2] Avia: 24 bit
A57: Faktor skala ideal | B57: =B56/($B$7*1000) -> 53.687091 | C57: count/g | D57: Bandingkan dengan hasil kalibrasi | E57: [2]
A58: LSB ideal | B58: =1000/B57 -> 18.626451 | C58: mg | D58: Resolusi kuantisasi | E58: [2]
A59: 5. Noise
...
